<?xml version="1.0"?>
<robot name = "ros_tree_robot">

    <material name="blue">
        <color rgba="0 0 0.8 1"/>
    </material>
    
    <material name="red">
        <color rgba="0.9 0 0.1 1"/>
    </material>
    
    <link name = "base_link">
        <visual>
            <origin rpy="0 0 0" xyz="0 0 0.1"/>
            <geometry>
                <cylinder length="0.2" radius="0.01"/>      
            </geometry>
            <material name="blue" />
        </visual>
    </link>
    
    <link name = "link2">
        <visual>
            <origin rpy="-1.5707 0 0" xyz="0.0 0.1 0.0"/>
            <geometry>
                <cylinder length="0.2" radius="0.01"/>      
            </geometry>
            <material name="red" />
        </visual>
    </link>
    
    <joint name = "joint1" type = "continuous">
        <parent link  = "base_link"/>
        <child  link  = "link2"/>
        <origin  rpy="0 0 0" xyz="0.0 0.0 0.2"/>
        <axis xyz="0 0 1"/>
    </joint>
    
    <link name = "link3">
        <visual>
            <origin rpy="0 -1.5707 0" xyz="-0.1 0 0"/>
            <geometry>
                <cylinder length="0.2" radius="0.01"/>      
            </geometry>
            <material name="blue" />
        </visual>
    </link>
    
    <joint name = "joint2" type = "continuous">
        <parent link  = "link2"/>
        <child  link  = "link3"/>
        <origin rpy="-1.5707 0 0" xyz="0 0.2 0.0"/>
        <axis xyz="0 0 1"/>
    </joint>
     
    <link name = "link4">
        <visual>
            <origin rpy="1.5707 0 0" xyz="0.0 0.05 0.0"/>
            <geometry>
                <cylinder length="0.1" radius="0.01"/>      
            </geometry>
            <material name="red" />
        </visual>
    </link>
        
    <joint name = "joint3" type = "continuous">
        <parent link  = "link3"/>
        <child  link  = "link4"/>
        <origin rpy="0 -1.5707 0" xyz="-0.2 0 0" />
        <axis xyz="0 0 1"/>
    </joint>
</robot>
    

